Traceback (most recent call last):
  File "c:\Users\brian\AppData\Local\Programs\Python\Python311\Lib\site-packages\jupyter_cache\executors\utils.py", line 58, in single_nb_execution
    executenb(
  File "c:\Users\brian\AppData\Local\Programs\Python\Python311\Lib\site-packages\nbclient\client.py", line 1314, in execute
    return NotebookClient(nb=nb, resources=resources, km=km, **kwargs).execute()
           ^^^^^^^^^^^^^^^^^^^^^^^^^^^^^^^^^^^^^^^^^^^^^^^^^^^^^^^^^^^^^^^^^^^^^
  File "C:\Users\brian\AppData\Roaming\Python\Python311\site-packages\jupyter_core\utils\__init__.py", line 165, in wrapped
    return loop.run_until_complete(inner)
           ^^^^^^^^^^^^^^^^^^^^^^^^^^^^^^
  File "c:\Users\brian\AppData\Local\Programs\Python\Python311\Lib\asyncio\base_events.py", line 653, in run_until_complete
    return future.result()
           ^^^^^^^^^^^^^^^
  File "c:\Users\brian\AppData\Local\Programs\Python\Python311\Lib\site-packages\nbclient\client.py", line 709, in async_execute
    await self.async_execute_cell(
  File "c:\Users\brian\AppData\Local\Programs\Python\Python311\Lib\site-packages\nbclient\client.py", line 1062, in async_execute_cell
    await self._check_raise_for_error(cell, cell_index, exec_reply)
  File "c:\Users\brian\AppData\Local\Programs\Python\Python311\Lib\site-packages\nbclient\client.py", line 918, in _check_raise_for_error
    raise CellExecutionError.from_cell_and_msg(cell, exec_reply_content)
nbclient.exceptions.CellExecutionError: An error occurred while executing the following cell:
------------------
hbat = pd.read_spss("datasets/HBAT.sav")
------------------


[1;31m---------------------------------------------------------------------------[0m
[1;31mModuleNotFoundError[0m                       Traceback (most recent call last)
File [1;32mc:\Users\brian\AppData\Local\Programs\Python\Python311\Lib\site-packages\pandas\compat\_optional.py:135[0m, in [0;36mimport_optional_dependency[1;34m(name, extra, errors, min_version)[0m
[0;32m    134[0m [38;5;28;01mtry[39;00m:
[1;32m--> 135[0m     module [38;5;241m=[39m [43mimportlib[49m[38;5;241;43m.[39;49m[43mimport_module[49m[43m([49m[43mname[49m[43m)[49m
[0;32m    136[0m [38;5;28;01mexcept[39;00m [38;5;167;01mImportError[39;00m:

File [1;32mc:\Users\brian\AppData\Local\Programs\Python\Python311\Lib\importlib\__init__.py:126[0m, in [0;36mimport_module[1;34m(name, package)[0m
[0;32m    125[0m         level [38;5;241m+[39m[38;5;241m=[39m [38;5;241m1[39m
[1;32m--> 126[0m [38;5;28;01mreturn[39;00m [43m_bootstrap[49m[38;5;241;43m.[39;49m[43m_gcd_import[49m[43m([49m[43mname[49m[43m[[49m[43mlevel[49m[43m:[49m[43m][49m[43m,[49m[43m [49m[43mpackage[49m[43m,[49m[43m [49m[43mlevel[49m[43m)[49m

File [1;32m<frozen importlib._bootstrap>:1204[0m, in [0;36m_gcd_import[1;34m(name, package, level)[0m

File [1;32m<frozen importlib._bootstrap>:1176[0m, in [0;36m_find_and_load[1;34m(name, import_)[0m

File [1;32m<frozen importlib._bootstrap>:1140[0m, in [0;36m_find_and_load_unlocked[1;34m(name, import_)[0m

[1;31mModuleNotFoundError[0m: No module named 'pyreadstat'

During handling of the above exception, another exception occurred:

[1;31mImportError[0m                               Traceback (most recent call last)
Cell [1;32mIn[16], line 1[0m
[1;32m----> 1[0m hbat [38;5;241m=[39m [43mpd[49m[38;5;241;43m.[39;49m[43mread_spss[49m[43m([49m[38;5;124;43m"[39;49m[38;5;124;43mdatasets/HBAT.sav[39;49m[38;5;124;43m"[39;49m[43m)[49m

File [1;32mc:\Users\brian\AppData\Local\Programs\Python\Python311\Lib\site-packages\pandas\io\spss.py:58[0m, in [0;36mread_spss[1;34m(path, usecols, convert_categoricals, dtype_backend)[0m
[0;32m     22[0m [38;5;28;01mdef[39;00m [38;5;21mread_spss[39m(
[0;32m     23[0m     path: [38;5;28mstr[39m [38;5;241m|[39m Path,
[0;32m     24[0m     usecols: Sequence[[38;5;28mstr[39m] [38;5;241m|[39m [38;5;28;01mNone[39;00m [38;5;241m=[39m [38;5;28;01mNone[39;00m,
[0;32m     25[0m     convert_categoricals: [38;5;28mbool[39m [38;5;241m=[39m [38;5;28;01mTrue[39;00m,
[0;32m     26[0m     dtype_backend: DtypeBackend [38;5;241m|[39m lib[38;5;241m.[39mNoDefault [38;5;241m=[39m lib[38;5;241m.[39mno_default,
[0;32m     27[0m ) [38;5;241m-[39m[38;5;241m>[39m DataFrame:
[0;32m     28[0m [38;5;250m    [39m[38;5;124;03m"""[39;00m
[0;32m     29[0m [38;5;124;03m    Load an SPSS file from the file path, returning a DataFrame.[39;00m
[0;32m     30[0m 
[1;32m   (...)[0m
[0;32m     56[0m [38;5;124;03m    >>> df = pd.read_spss("spss_data.sav")  # doctest: +SKIP[39;00m
[0;32m     57[0m [38;5;124;03m    """[39;00m
[1;32m---> 58[0m     pyreadstat [38;5;241m=[39m [43mimport_optional_dependency[49m[43m([49m[38;5;124;43m"[39;49m[38;5;124;43mpyreadstat[39;49m[38;5;124;43m"[39;49m[43m)[49m
[0;32m     59[0m     check_dtype_backend(dtype_backend)
[0;32m     61[0m     [38;5;28;01mif[39;00m usecols [38;5;129;01mis[39;00m [38;5;129;01mnot[39;00m [38;5;28;01mNone[39;00m:

File [1;32mc:\Users\brian\AppData\Local\Programs\Python\Python311\Lib\site-packages\pandas\compat\_optional.py:138[0m, in [0;36mimport_optional_dependency[1;34m(name, extra, errors, min_version)[0m
[0;32m    136[0m [38;5;28;01mexcept[39;00m [38;5;167;01mImportError[39;00m:
[0;32m    137[0m     [38;5;28;01mif[39;00m errors [38;5;241m==[39m [38;5;124m"[39m[38;5;124mraise[39m[38;5;124m"[39m:
[1;32m--> 138[0m         [38;5;28;01mraise[39;00m [38;5;167;01mImportError[39;00m(msg)
[0;32m    139[0m     [38;5;28;01mreturn[39;00m [38;5;28;01mNone[39;00m
[0;32m    141[0m [38;5;66;03m# Handle submodules: if we have submodule, grab parent module from sys.modules[39;00m

[1;31mImportError[0m: Missing optional dependency 'pyreadstat'.  Use pip or conda to install pyreadstat.

